INFO 2025-04-21 23:32:47,664 autoreload Watching for file changes with StatReloader
ERROR 2025-04-21 23:33:10,343 basehttp "GET / HTTP/1.1" 500 59
ERROR 2025-04-21 23:33:14,242 basehttp "GET /favicon.ico HTTP/1.1" 500 59
INFO 2025-04-21 23:36:26,288 autoreload Watching for file changes with StatReloader
WARNING 2025-04-21 23:36:35,398 log Not Found: /
WARNING 2025-04-21 23:36:35,399 basehttp "GET / HTTP/1.1" 404 2644
WARNING 2025-04-21 23:36:35,543 log Not Found: /favicon.ico
WARNING 2025-04-21 23:36:35,543 basehttp "GET /favicon.ico HTTP/1.1" 404 2695
INFO 2025-04-21 23:36:44,241 basehttp "GET /admin HTTP/1.1" 301 0
INFO 2025-04-21 23:36:44,246 basehttp "GET /admin/ HTTP/1.1" 302 0
INFO 2025-04-21 23:36:44,272 basehttp "GET /admin/login/?next=/admin/ HTTP/1.1" 200 4198
INFO 2025-04-21 23:36:44,280 basehttp "GET /static/admin/css/base.css HTTP/1.1" 304 0
INFO 2025-04-21 23:36:44,280 basehttp "GET /static/admin/css/dark_mode.css HTTP/1.1" 304 0
INFO 2025-04-21 23:36:44,281 basehttp "GET /static/admin/js/theme.js HTTP/1.1" 304 0
INFO 2025-04-21 23:36:44,326 basehttp "GET /static/admin/css/nav_sidebar.css HTTP/1.1" 304 0
INFO 2025-04-21 23:36:44,326 basehttp "GET /static/admin/css/login.css HTTP/1.1" 304 0
INFO 2025-04-21 23:36:44,326 basehttp "GET /static/admin/css/responsive.css HTTP/1.1" 304 0
INFO 2025-04-21 23:36:44,329 basehttp "GET /static/admin/js/nav_sidebar.js HTTP/1.1" 304 0
INFO 2025-04-21 23:36:49,854 basehttp "POST /admin/login/?next=/admin/ HTTP/1.1" 302 0
INFO 2025-04-21 23:36:49,865 basehttp "GET /admin/ HTTP/1.1" 200 5515
INFO 2025-04-21 23:36:49,884 basehttp "GET /static/admin/css/dashboard.css HTTP/1.1" 304 0
INFO 2025-04-21 23:36:49,885 basehttp "GET /static/admin/img/icon-addlink.svg HTTP/1.1" 304 0
INFO 2025-04-21 23:36:49,885 basehttp "GET /static/admin/img/icon-changelink.svg HTTP/1.1" 304 0
INFO 2025-04-21 23:38:18,352 basehttp "POST /api/v1/auth/login/ HTTP/1.1" 200 566
INFO 2025-04-21 23:38:31,170 basehttp "POST /api/v1/auth/login/ HTTP/1.1" 200 566
ERROR 2025-04-21 23:38:33,224 log Internal Server Error: /api/v1/tenants/
Traceback (most recent call last):
  File "C:\Users\Administrator\AppData\Local\Packages\PythonSoftwareFoundation.Python.3.13_qbz5n2kfra8p0\LocalCache\local-packages\Python313\site-packages\rest_framework\views.py", line 503, in dispatch
    self.initial(request, *args, **kwargs)
    ~~~~~~~~~~~~^^^^^^^^^^^^^^^^^^^^^^^^^^
  File "C:\Users\Administrator\AppData\Local\Packages\PythonSoftwareFoundation.Python.3.13_qbz5n2kfra8p0\LocalCache\local-packages\Python313\site-packages\rest_framework\views.py", line 421, in initial
    self.check_permissions(request)
    ~~~~~~~~~~~~~~~~~~~~~~^^^^^^^^^
  File "C:\Users\Administrator\AppData\Local\Packages\PythonSoftwareFoundation.Python.3.13_qbz5n2kfra8p0\LocalCache\local-packages\Python313\site-packages\rest_framework\views.py", line 339, in check_permissions
    self.permission_denied(
    ~~~~~~~~~~~~~~~~~~~~~~^
        request,
        ^^^^^^^^
        message=getattr(permission, 'message', None),
        ^^^^^^^^^^^^^^^^^^^^^^^^^^^^^^^^^^^^^^^^^^^^^
        code=getattr(permission, 'code', None)
        ^^^^^^^^^^^^^^^^^^^^^^^^^^^^^^^^^^^^^^
    )
    ^
  File "C:\Users\Administrator\AppData\Local\Packages\PythonSoftwareFoundation.Python.3.13_qbz5n2kfra8p0\LocalCache\local-packages\Python313\site-packages\rest_framework\views.py", line 181, in permission_denied
    raise exceptions.PermissionDenied(detail=message, code=code)
rest_framework.exceptions.PermissionDenied: 您没有执行该操作的权限。

During handling of the above exception, another exception occurred:

Traceback (most recent call last):
  File "C:\Users\Administrator\AppData\Local\Packages\PythonSoftwareFoundation.Python.3.13_qbz5n2kfra8p0\LocalCache\local-packages\Python313\site-packages\django\utils\module_loading.py", line 30, in import_string
    return cached_import(module_path, class_name)
  File "C:\Users\Administrator\AppData\Local\Packages\PythonSoftwareFoundation.Python.3.13_qbz5n2kfra8p0\LocalCache\local-packages\Python313\site-packages\django\utils\module_loading.py", line 16, in cached_import
    return getattr(module, class_name)
AttributeError: module 'common.exceptions' has no attribute 'custom_exception_handler'

The above exception was the direct cause of the following exception:

Traceback (most recent call last):
  File "C:\Users\Administrator\AppData\Local\Packages\PythonSoftwareFoundation.Python.3.13_qbz5n2kfra8p0\LocalCache\local-packages\Python313\site-packages\rest_framework\settings.py", line 179, in import_from_string
    return import_string(val)
  File "C:\Users\Administrator\AppData\Local\Packages\PythonSoftwareFoundation.Python.3.13_qbz5n2kfra8p0\LocalCache\local-packages\Python313\site-packages\django\utils\module_loading.py", line 32, in import_string
    raise ImportError(
    ...<2 lines>...
    ) from err
ImportError: Module "common.exceptions" does not define a "custom_exception_handler" attribute/class

During handling of the above exception, another exception occurred:

Traceback (most recent call last):
  File "C:\Users\Administrator\AppData\Local\Packages\PythonSoftwareFoundation.Python.3.13_qbz5n2kfra8p0\LocalCache\local-packages\Python313\site-packages\django\core\handlers\exception.py", line 55, in inner
    response = get_response(request)
  File "C:\Users\Administrator\AppData\Local\Packages\PythonSoftwareFoundation.Python.3.13_qbz5n2kfra8p0\LocalCache\local-packages\Python313\site-packages\django\core\handlers\base.py", line 197, in _get_response
    response = wrapped_callback(request, *callback_args, **callback_kwargs)
  File "C:\Users\Administrator\AppData\Local\Packages\PythonSoftwareFoundation.Python.3.13_qbz5n2kfra8p0\LocalCache\local-packages\Python313\site-packages\django\views\decorators\csrf.py", line 65, in _view_wrapper
    return view_func(request, *args, **kwargs)
  File "C:\Users\Administrator\AppData\Local\Packages\PythonSoftwareFoundation.Python.3.13_qbz5n2kfra8p0\LocalCache\local-packages\Python313\site-packages\django\views\generic\base.py", line 104, in view
    return self.dispatch(request, *args, **kwargs)
           ~~~~~~~~~~~~~^^^^^^^^^^^^^^^^^^^^^^^^^^
  File "C:\Users\Administrator\AppData\Local\Packages\PythonSoftwareFoundation.Python.3.13_qbz5n2kfra8p0\LocalCache\local-packages\Python313\site-packages\rest_framework\views.py", line 515, in dispatch
    response = self.handle_exception(exc)
  File "C:\Users\Administrator\AppData\Local\Packages\PythonSoftwareFoundation.Python.3.13_qbz5n2kfra8p0\LocalCache\local-packages\Python313\site-packages\rest_framework\views.py", line 469, in handle_exception
    exception_handler = self.get_exception_handler()
  File "C:\Users\Administrator\AppData\Local\Packages\PythonSoftwareFoundation.Python.3.13_qbz5n2kfra8p0\LocalCache\local-packages\Python313\site-packages\rest_framework\views.py", line 304, in get_exception_handler
    return self.settings.EXCEPTION_HANDLER
           ^^^^^^^^^^^^^^^^^^^^^^^^^^^^^^^
  File "C:\Users\Administrator\AppData\Local\Packages\PythonSoftwareFoundation.Python.3.13_qbz5n2kfra8p0\LocalCache\local-packages\Python313\site-packages\rest_framework\settings.py", line 227, in __getattr__
    val = perform_import(val, attr)
  File "C:\Users\Administrator\AppData\Local\Packages\PythonSoftwareFoundation.Python.3.13_qbz5n2kfra8p0\LocalCache\local-packages\Python313\site-packages\rest_framework\settings.py", line 168, in perform_import
    return import_from_string(val, setting_name)
  File "C:\Users\Administrator\AppData\Local\Packages\PythonSoftwareFoundation.Python.3.13_qbz5n2kfra8p0\LocalCache\local-packages\Python313\site-packages\rest_framework\settings.py", line 182, in import_from_string
    raise ImportError(msg)
ImportError: Could not import 'common.exceptions.custom_exception_handler' for API setting 'EXCEPTION_HANDLER'. ImportError: Module "common.exceptions" does not define a "custom_exception_handler" attribute/class.
ERROR 2025-04-21 23:38:33,229 basehttp "POST /api/v1/tenants/ HTTP/1.1" 500 136902
INFO 2025-04-21 23:38:53,374 autoreload D:\GitHub\integrated_project\core\settings.py changed, reloading.
INFO 2025-04-21 23:38:53,701 autoreload Watching for file changes with StatReloader
INFO 2025-04-21 23:39:00,790 autoreload Watching for file changes with StatReloader
INFO 2025-04-21 23:39:07,586 basehttp "POST /api/v1/auth/login/ HTTP/1.1" 200 566
INFO 2025-04-21 23:41:49,525 autoreload D:\GitHub\integrated_project\core\settings.py changed, reloading.
INFO 2025-04-21 23:41:49,637 autoreload D:\GitHub\integrated_project\core\settings.py changed, reloading.
INFO 2025-04-21 23:41:49,841 autoreload Watching for file changes with StatReloader
INFO 2025-04-21 23:41:49,949 autoreload Watching for file changes with StatReloader
INFO 2025-04-21 23:42:08,426 basehttp "POST /api/v1/auth/login/ HTTP/1.1" 200 566
ERROR 2025-04-21 23:42:10,490 log Internal Server Error: /api/v1/users/me/
Traceback (most recent call last):
  File "C:\Users\Administrator\AppData\Local\Packages\PythonSoftwareFoundation.Python.3.13_qbz5n2kfra8p0\LocalCache\local-packages\Python313\site-packages\rest_framework\views.py", line 503, in dispatch
    self.initial(request, *args, **kwargs)
    ~~~~~~~~~~~~^^^^^^^^^^^^^^^^^^^^^^^^^^
  File "C:\Users\Administrator\AppData\Local\Packages\PythonSoftwareFoundation.Python.3.13_qbz5n2kfra8p0\LocalCache\local-packages\Python313\site-packages\rest_framework\views.py", line 421, in initial
    self.check_permissions(request)
    ~~~~~~~~~~~~~~~~~~~~~~^^^^^^^^^
  File "C:\Users\Administrator\AppData\Local\Packages\PythonSoftwareFoundation.Python.3.13_qbz5n2kfra8p0\LocalCache\local-packages\Python313\site-packages\rest_framework\views.py", line 339, in check_permissions
    self.permission_denied(
    ~~~~~~~~~~~~~~~~~~~~~~^
        request,
        ^^^^^^^^
        message=getattr(permission, 'message', None),
        ^^^^^^^^^^^^^^^^^^^^^^^^^^^^^^^^^^^^^^^^^^^^^
        code=getattr(permission, 'code', None)
        ^^^^^^^^^^^^^^^^^^^^^^^^^^^^^^^^^^^^^^
    )
    ^
  File "C:\Users\Administrator\AppData\Local\Packages\PythonSoftwareFoundation.Python.3.13_qbz5n2kfra8p0\LocalCache\local-packages\Python313\site-packages\rest_framework\views.py", line 180, in permission_denied
    raise exceptions.NotAuthenticated()
rest_framework.exceptions.NotAuthenticated: 身份认证信息未提供。

During handling of the above exception, another exception occurred:

Traceback (most recent call last):
  File "C:\Users\Administrator\AppData\Local\Packages\PythonSoftwareFoundation.Python.3.13_qbz5n2kfra8p0\LocalCache\local-packages\Python313\site-packages\django\utils\module_loading.py", line 30, in import_string
    return cached_import(module_path, class_name)
  File "C:\Users\Administrator\AppData\Local\Packages\PythonSoftwareFoundation.Python.3.13_qbz5n2kfra8p0\LocalCache\local-packages\Python313\site-packages\django\utils\module_loading.py", line 16, in cached_import
    return getattr(module, class_name)
AttributeError: module 'common.exceptions' has no attribute 'custom_exception_handler'

The above exception was the direct cause of the following exception:

Traceback (most recent call last):
  File "C:\Users\Administrator\AppData\Local\Packages\PythonSoftwareFoundation.Python.3.13_qbz5n2kfra8p0\LocalCache\local-packages\Python313\site-packages\rest_framework\settings.py", line 179, in import_from_string
    return import_string(val)
  File "C:\Users\Administrator\AppData\Local\Packages\PythonSoftwareFoundation.Python.3.13_qbz5n2kfra8p0\LocalCache\local-packages\Python313\site-packages\django\utils\module_loading.py", line 32, in import_string
    raise ImportError(
    ...<2 lines>...
    ) from err
ImportError: Module "common.exceptions" does not define a "custom_exception_handler" attribute/class

During handling of the above exception, another exception occurred:

Traceback (most recent call last):
  File "C:\Users\Administrator\AppData\Local\Packages\PythonSoftwareFoundation.Python.3.13_qbz5n2kfra8p0\LocalCache\local-packages\Python313\site-packages\django\core\handlers\exception.py", line 55, in inner
    response = get_response(request)
  File "C:\Users\Administrator\AppData\Local\Packages\PythonSoftwareFoundation.Python.3.13_qbz5n2kfra8p0\LocalCache\local-packages\Python313\site-packages\django\core\handlers\base.py", line 197, in _get_response
    response = wrapped_callback(request, *callback_args, **callback_kwargs)
  File "C:\Users\Administrator\AppData\Local\Packages\PythonSoftwareFoundation.Python.3.13_qbz5n2kfra8p0\LocalCache\local-packages\Python313\site-packages\django\views\decorators\csrf.py", line 65, in _view_wrapper
    return view_func(request, *args, **kwargs)
  File "C:\Users\Administrator\AppData\Local\Packages\PythonSoftwareFoundation.Python.3.13_qbz5n2kfra8p0\LocalCache\local-packages\Python313\site-packages\django\views\generic\base.py", line 104, in view
    return self.dispatch(request, *args, **kwargs)
           ~~~~~~~~~~~~~^^^^^^^^^^^^^^^^^^^^^^^^^^
  File "C:\Users\Administrator\AppData\Local\Packages\PythonSoftwareFoundation.Python.3.13_qbz5n2kfra8p0\LocalCache\local-packages\Python313\site-packages\rest_framework\views.py", line 515, in dispatch
    response = self.handle_exception(exc)
  File "C:\Users\Administrator\AppData\Local\Packages\PythonSoftwareFoundation.Python.3.13_qbz5n2kfra8p0\LocalCache\local-packages\Python313\site-packages\rest_framework\views.py", line 469, in handle_exception
    exception_handler = self.get_exception_handler()
  File "C:\Users\Administrator\AppData\Local\Packages\PythonSoftwareFoundation.Python.3.13_qbz5n2kfra8p0\LocalCache\local-packages\Python313\site-packages\rest_framework\views.py", line 304, in get_exception_handler
    return self.settings.EXCEPTION_HANDLER
           ^^^^^^^^^^^^^^^^^^^^^^^^^^^^^^^
  File "C:\Users\Administrator\AppData\Local\Packages\PythonSoftwareFoundation.Python.3.13_qbz5n2kfra8p0\LocalCache\local-packages\Python313\site-packages\rest_framework\settings.py", line 227, in __getattr__
    val = perform_import(val, attr)
  File "C:\Users\Administrator\AppData\Local\Packages\PythonSoftwareFoundation.Python.3.13_qbz5n2kfra8p0\LocalCache\local-packages\Python313\site-packages\rest_framework\settings.py", line 168, in perform_import
    return import_from_string(val, setting_name)
  File "C:\Users\Administrator\AppData\Local\Packages\PythonSoftwareFoundation.Python.3.13_qbz5n2kfra8p0\LocalCache\local-packages\Python313\site-packages\rest_framework\settings.py", line 182, in import_from_string
    raise ImportError(msg)
ImportError: Could not import 'common.exceptions.custom_exception_handler' for API setting 'EXCEPTION_HANDLER'. ImportError: Module "common.exceptions" does not define a "custom_exception_handler" attribute/class.
ERROR 2025-04-21 23:42:10,509 basehttp "GET /api/v1/users/me/ HTTP/1.1" 500 137050
INFO 2025-04-21 23:42:35,882 autoreload D:\GitHub\integrated_project\common\exceptions\__init__.py changed, reloading.
INFO 2025-04-21 23:42:36,192 autoreload Watching for file changes with StatReloader
INFO 2025-04-21 23:42:47,317 autoreload D:\GitHub\integrated_project\common\authentication\jwt_auth.py changed, reloading.
INFO 2025-04-21 23:42:47,629 autoreload Watching for file changes with StatReloader
INFO 2025-04-21 23:42:47,965 autoreload D:\GitHub\integrated_project\common\authentication\jwt_auth.py changed, reloading.
INFO 2025-04-21 23:42:48,276 autoreload Watching for file changes with StatReloader
INFO 2025-04-21 23:43:00,457 autoreload D:\GitHub\integrated_project\core\settings.py changed, reloading.
INFO 2025-04-21 23:43:00,765 autoreload Watching for file changes with StatReloader
INFO 2025-04-21 23:43:00,822 autoreload D:\GitHub\integrated_project\core\settings.py changed, reloading.
INFO 2025-04-21 23:43:01,128 autoreload Watching for file changes with StatReloader
INFO 2025-04-21 23:43:07,914 autoreload D:\GitHub\integrated_project\core\settings.py changed, reloading.
INFO 2025-04-21 23:43:08,225 autoreload Watching for file changes with StatReloader
INFO 2025-04-21 23:43:08,270 autoreload D:\GitHub\integrated_project\core\settings.py changed, reloading.
INFO 2025-04-21 23:43:08,584 autoreload Watching for file changes with StatReloader
INFO 2025-04-21 23:43:13,998 autoreload Watching for file changes with StatReloader
INFO 2025-04-21 23:43:26,981 basehttp "POST /api/v1/auth/login/ HTTP/1.1" 200 566
INFO 2025-04-21 23:43:29,034 basehttp "GET /api/v1/users/me/ HTTP/1.1" 200 299
INFO 2025-04-21 23:44:04,614 basehttp "GET /api/v1/docs/ HTTP/1.1" 200 4667
ERROR 2025-04-21 23:44:05,641 log Internal Server Error: /api/v1/schema/
Traceback (most recent call last):
  File "C:\Users\Administrator\AppData\Local\Packages\PythonSoftwareFoundation.Python.3.13_qbz5n2kfra8p0\LocalCache\local-packages\Python313\site-packages\django\core\handlers\exception.py", line 55, in inner
    response = get_response(request)
  File "C:\Users\Administrator\AppData\Local\Packages\PythonSoftwareFoundation.Python.3.13_qbz5n2kfra8p0\LocalCache\local-packages\Python313\site-packages\django\core\handlers\base.py", line 197, in _get_response
    response = wrapped_callback(request, *callback_args, **callback_kwargs)
  File "C:\Users\Administrator\AppData\Local\Packages\PythonSoftwareFoundation.Python.3.13_qbz5n2kfra8p0\LocalCache\local-packages\Python313\site-packages\django\views\decorators\csrf.py", line 65, in _view_wrapper
    return view_func(request, *args, **kwargs)
  File "C:\Users\Administrator\AppData\Local\Packages\PythonSoftwareFoundation.Python.3.13_qbz5n2kfra8p0\LocalCache\local-packages\Python313\site-packages\django\views\generic\base.py", line 104, in view
    return self.dispatch(request, *args, **kwargs)
           ~~~~~~~~~~~~~^^^^^^^^^^^^^^^^^^^^^^^^^^
  File "C:\Users\Administrator\AppData\Local\Packages\PythonSoftwareFoundation.Python.3.13_qbz5n2kfra8p0\LocalCache\local-packages\Python313\site-packages\rest_framework\views.py", line 515, in dispatch
    response = self.handle_exception(exc)
  File "C:\Users\Administrator\AppData\Local\Packages\PythonSoftwareFoundation.Python.3.13_qbz5n2kfra8p0\LocalCache\local-packages\Python313\site-packages\rest_framework\views.py", line 475, in handle_exception
    self.raise_uncaught_exception(exc)
    ~~~~~~~~~~~~~~~~~~~~~~~~~~~~~^^^^^
  File "C:\Users\Administrator\AppData\Local\Packages\PythonSoftwareFoundation.Python.3.13_qbz5n2kfra8p0\LocalCache\local-packages\Python313\site-packages\rest_framework\views.py", line 486, in raise_uncaught_exception
    raise exc
  File "C:\Users\Administrator\AppData\Local\Packages\PythonSoftwareFoundation.Python.3.13_qbz5n2kfra8p0\LocalCache\local-packages\Python313\site-packages\rest_framework\views.py", line 512, in dispatch
    response = handler(request, *args, **kwargs)
  File "C:\Users\Administrator\AppData\Local\Packages\PythonSoftwareFoundation.Python.3.13_qbz5n2kfra8p0\LocalCache\local-packages\Python313\site-packages\drf_spectacular\views.py", line 84, in get
    return self._get_schema_response(request)
           ~~~~~~~~~~~~~~~~~~~~~~~~~^^^^^^^^^
  File "C:\Users\Administrator\AppData\Local\Packages\PythonSoftwareFoundation.Python.3.13_qbz5n2kfra8p0\LocalCache\local-packages\Python313\site-packages\drf_spectacular\views.py", line 92, in _get_schema_response
    data=generator.get_schema(request=request, public=self.serve_public),
         ~~~~~~~~~~~~~~~~~~~~^^^^^^^^^^^^^^^^^^^^^^^^^^^^^^^^^^^^^^^^^^^
  File "C:\Users\Administrator\AppData\Local\Packages\PythonSoftwareFoundation.Python.3.13_qbz5n2kfra8p0\LocalCache\local-packages\Python313\site-packages\drf_spectacular\generators.py", line 285, in get_schema
    paths=self.parse(request, public),
          ~~~~~~~~~~^^^^^^^^^^^^^^^^^
  File "C:\Users\Administrator\AppData\Local\Packages\PythonSoftwareFoundation.Python.3.13_qbz5n2kfra8p0\LocalCache\local-packages\Python313\site-packages\drf_spectacular\generators.py", line 256, in parse
    operation = view.schema.get_operation(
        path, path_regex, path_prefix, method, self.registry
    )
  File "C:\Users\Administrator\AppData\Local\Packages\PythonSoftwareFoundation.Python.3.13_qbz5n2kfra8p0\LocalCache\local-packages\Python313\site-packages\drf_spectacular\openapi.py", line 112, in get_operation
    operation['responses'] = self._get_response_bodies()
                             ~~~~~~~~~~~~~~~~~~~~~~~~~^^
  File "C:\Users\Administrator\AppData\Local\Packages\PythonSoftwareFoundation.Python.3.13_qbz5n2kfra8p0\LocalCache\local-packages\Python313\site-packages\drf_spectacular\openapi.py", line 1397, in _get_response_bodies
    return {'200': self._get_response_for_code(response_serializers, '200', direction=direction)}
                   ~~~~~~~~~~~~~~~~~~~~~~~~~~~^^^^^^^^^^^^^^^^^^^^^^^^^^^^^^^^^^^^^^^^^^^^^^^^^^
  File "C:\Users\Administrator\AppData\Local\Packages\PythonSoftwareFoundation.Python.3.13_qbz5n2kfra8p0\LocalCache\local-packages\Python313\site-packages\drf_spectacular\openapi.py", line 1453, in _get_response_for_code
    component = self.resolve_serializer(serializer, direction)
  File "C:\Users\Administrator\AppData\Local\Packages\PythonSoftwareFoundation.Python.3.13_qbz5n2kfra8p0\LocalCache\local-packages\Python313\site-packages\drf_spectacular\openapi.py", line 1648, in resolve_serializer
    component.schema = self._map_serializer(serializer, direction, bypass_extensions)
                       ~~~~~~~~~~~~~~~~~~~~^^^^^^^^^^^^^^^^^^^^^^^^^^^^^^^^^^^^^^^^^^
  File "C:\Users\Administrator\AppData\Local\Packages\PythonSoftwareFoundation.Python.3.13_qbz5n2kfra8p0\LocalCache\local-packages\Python313\site-packages\drf_spectacular\openapi.py", line 949, in _map_serializer
    schema = self._map_basic_serializer(serializer, direction)
  File "C:\Users\Administrator\AppData\Local\Packages\PythonSoftwareFoundation.Python.3.13_qbz5n2kfra8p0\LocalCache\local-packages\Python313\site-packages\drf_spectacular\openapi.py", line 1048, in _map_basic_serializer
    schema = self._map_serializer_field(field, direction)
  File "C:\Users\Administrator\AppData\Local\Packages\PythonSoftwareFoundation.Python.3.13_qbz5n2kfra8p0\LocalCache\local-packages\Python313\site-packages\drf_spectacular\openapi.py", line 684, in _map_serializer_field
    component = self.resolve_serializer(field, direction)
  File "C:\Users\Administrator\AppData\Local\Packages\PythonSoftwareFoundation.Python.3.13_qbz5n2kfra8p0\LocalCache\local-packages\Python313\site-packages\drf_spectacular\openapi.py", line 1648, in resolve_serializer
    component.schema = self._map_serializer(serializer, direction, bypass_extensions)
                       ~~~~~~~~~~~~~~~~~~~~^^^^^^^^^^^^^^^^^^^^^^^^^^^^^^^^^^^^^^^^^^
  File "C:\Users\Administrator\AppData\Local\Packages\PythonSoftwareFoundation.Python.3.13_qbz5n2kfra8p0\LocalCache\local-packages\Python313\site-packages\drf_spectacular\openapi.py", line 949, in _map_serializer
    schema = self._map_basic_serializer(serializer, direction)
  File "C:\Users\Administrator\AppData\Local\Packages\PythonSoftwareFoundation.Python.3.13_qbz5n2kfra8p0\LocalCache\local-packages\Python313\site-packages\drf_spectacular\openapi.py", line 1042, in _map_basic_serializer
    for field in serializer.fields.values():
                 ^^^^^^^^^^^^^^^^^
  File "C:\Users\Administrator\AppData\Local\Packages\PythonSoftwareFoundation.Python.3.13_qbz5n2kfra8p0\LocalCache\local-packages\Python313\site-packages\django\utils\functional.py", line 47, in __get__
    res = instance.__dict__[self.name] = self.func(instance)
                                         ~~~~~~~~~^^^^^^^^^^
  File "C:\Users\Administrator\AppData\Local\Packages\PythonSoftwareFoundation.Python.3.13_qbz5n2kfra8p0\LocalCache\local-packages\Python313\site-packages\rest_framework\serializers.py", line 375, in fields
    fields[key] = value
    ~~~~~~^^^^^
  File "C:\Users\Administrator\AppData\Local\Packages\PythonSoftwareFoundation.Python.3.13_qbz5n2kfra8p0\LocalCache\local-packages\Python313\site-packages\rest_framework\utils\serializer_helpers.py", line 167, in __setitem__
    field.bind(field_name=key, parent=self.serializer)
    ~~~~~~~~~~^^^^^^^^^^^^^^^^^^^^^^^^^^^^^^^^^^^^^^^^
  File "C:\Users\Administrator\AppData\Local\Packages\PythonSoftwareFoundation.Python.3.13_qbz5n2kfra8p0\LocalCache\local-packages\Python313\site-packages\rest_framework\fields.py", line 358, in bind
    assert self.source != field_name, (
           ^^^^^^^^^^^^^^^^^^^^^^^^^
AssertionError: It is redundant to specify `source='display_name'` on field 'CharField' in serializer 'UserMinimalSerializer', because it is the same as the field name. Remove the `source` keyword argument.
ERROR 2025-04-21 23:44:05,645 basehttp "GET /api/v1/schema/ HTTP/1.1" 500 202876
ERROR 2025-04-21 23:44:05,674 log Internal Server Error: /api/v1/schema/
Traceback (most recent call last):
  File "C:\Users\Administrator\AppData\Local\Packages\PythonSoftwareFoundation.Python.3.13_qbz5n2kfra8p0\LocalCache\local-packages\Python313\site-packages\django\core\handlers\exception.py", line 55, in inner
    response = get_response(request)
  File "C:\Users\Administrator\AppData\Local\Packages\PythonSoftwareFoundation.Python.3.13_qbz5n2kfra8p0\LocalCache\local-packages\Python313\site-packages\django\core\handlers\base.py", line 197, in _get_response
    response = wrapped_callback(request, *callback_args, **callback_kwargs)
  File "C:\Users\Administrator\AppData\Local\Packages\PythonSoftwareFoundation.Python.3.13_qbz5n2kfra8p0\LocalCache\local-packages\Python313\site-packages\django\views\decorators\csrf.py", line 65, in _view_wrapper
    return view_func(request, *args, **kwargs)
  File "C:\Users\Administrator\AppData\Local\Packages\PythonSoftwareFoundation.Python.3.13_qbz5n2kfra8p0\LocalCache\local-packages\Python313\site-packages\django\views\generic\base.py", line 104, in view
    return self.dispatch(request, *args, **kwargs)
           ~~~~~~~~~~~~~^^^^^^^^^^^^^^^^^^^^^^^^^^
  File "C:\Users\Administrator\AppData\Local\Packages\PythonSoftwareFoundation.Python.3.13_qbz5n2kfra8p0\LocalCache\local-packages\Python313\site-packages\rest_framework\views.py", line 515, in dispatch
    response = self.handle_exception(exc)
  File "C:\Users\Administrator\AppData\Local\Packages\PythonSoftwareFoundation.Python.3.13_qbz5n2kfra8p0\LocalCache\local-packages\Python313\site-packages\rest_framework\views.py", line 475, in handle_exception
    self.raise_uncaught_exception(exc)
    ~~~~~~~~~~~~~~~~~~~~~~~~~~~~~^^^^^
  File "C:\Users\Administrator\AppData\Local\Packages\PythonSoftwareFoundation.Python.3.13_qbz5n2kfra8p0\LocalCache\local-packages\Python313\site-packages\rest_framework\views.py", line 486, in raise_uncaught_exception
    raise exc
  File "C:\Users\Administrator\AppData\Local\Packages\PythonSoftwareFoundation.Python.3.13_qbz5n2kfra8p0\LocalCache\local-packages\Python313\site-packages\rest_framework\views.py", line 512, in dispatch
    response = handler(request, *args, **kwargs)
  File "C:\Users\Administrator\AppData\Local\Packages\PythonSoftwareFoundation.Python.3.13_qbz5n2kfra8p0\LocalCache\local-packages\Python313\site-packages\drf_spectacular\views.py", line 84, in get
    return self._get_schema_response(request)
           ~~~~~~~~~~~~~~~~~~~~~~~~~^^^^^^^^^
  File "C:\Users\Administrator\AppData\Local\Packages\PythonSoftwareFoundation.Python.3.13_qbz5n2kfra8p0\LocalCache\local-packages\Python313\site-packages\drf_spectacular\views.py", line 92, in _get_schema_response
    data=generator.get_schema(request=request, public=self.serve_public),
         ~~~~~~~~~~~~~~~~~~~~^^^^^^^^^^^^^^^^^^^^^^^^^^^^^^^^^^^^^^^^^^^
  File "C:\Users\Administrator\AppData\Local\Packages\PythonSoftwareFoundation.Python.3.13_qbz5n2kfra8p0\LocalCache\local-packages\Python313\site-packages\drf_spectacular\generators.py", line 285, in get_schema
    paths=self.parse(request, public),
          ~~~~~~~~~~^^^^^^^^^^^^^^^^^
  File "C:\Users\Administrator\AppData\Local\Packages\PythonSoftwareFoundation.Python.3.13_qbz5n2kfra8p0\LocalCache\local-packages\Python313\site-packages\drf_spectacular\generators.py", line 256, in parse
    operation = view.schema.get_operation(
        path, path_regex, path_prefix, method, self.registry
    )
  File "C:\Users\Administrator\AppData\Local\Packages\PythonSoftwareFoundation.Python.3.13_qbz5n2kfra8p0\LocalCache\local-packages\Python313\site-packages\drf_spectacular\openapi.py", line 112, in get_operation
    operation['responses'] = self._get_response_bodies()
                             ~~~~~~~~~~~~~~~~~~~~~~~~~^^
  File "C:\Users\Administrator\AppData\Local\Packages\PythonSoftwareFoundation.Python.3.13_qbz5n2kfra8p0\LocalCache\local-packages\Python313\site-packages\drf_spectacular\openapi.py", line 1397, in _get_response_bodies
    return {'200': self._get_response_for_code(response_serializers, '200', direction=direction)}
                   ~~~~~~~~~~~~~~~~~~~~~~~~~~~^^^^^^^^^^^^^^^^^^^^^^^^^^^^^^^^^^^^^^^^^^^^^^^^^^
  File "C:\Users\Administrator\AppData\Local\Packages\PythonSoftwareFoundation.Python.3.13_qbz5n2kfra8p0\LocalCache\local-packages\Python313\site-packages\drf_spectacular\openapi.py", line 1453, in _get_response_for_code
    component = self.resolve_serializer(serializer, direction)
  File "C:\Users\Administrator\AppData\Local\Packages\PythonSoftwareFoundation.Python.3.13_qbz5n2kfra8p0\LocalCache\local-packages\Python313\site-packages\drf_spectacular\openapi.py", line 1648, in resolve_serializer
    component.schema = self._map_serializer(serializer, direction, bypass_extensions)
                       ~~~~~~~~~~~~~~~~~~~~^^^^^^^^^^^^^^^^^^^^^^^^^^^^^^^^^^^^^^^^^^
  File "C:\Users\Administrator\AppData\Local\Packages\PythonSoftwareFoundation.Python.3.13_qbz5n2kfra8p0\LocalCache\local-packages\Python313\site-packages\drf_spectacular\openapi.py", line 949, in _map_serializer
    schema = self._map_basic_serializer(serializer, direction)
  File "C:\Users\Administrator\AppData\Local\Packages\PythonSoftwareFoundation.Python.3.13_qbz5n2kfra8p0\LocalCache\local-packages\Python313\site-packages\drf_spectacular\openapi.py", line 1048, in _map_basic_serializer
    schema = self._map_serializer_field(field, direction)
  File "C:\Users\Administrator\AppData\Local\Packages\PythonSoftwareFoundation.Python.3.13_qbz5n2kfra8p0\LocalCache\local-packages\Python313\site-packages\drf_spectacular\openapi.py", line 684, in _map_serializer_field
    component = self.resolve_serializer(field, direction)
  File "C:\Users\Administrator\AppData\Local\Packages\PythonSoftwareFoundation.Python.3.13_qbz5n2kfra8p0\LocalCache\local-packages\Python313\site-packages\drf_spectacular\openapi.py", line 1648, in resolve_serializer
    component.schema = self._map_serializer(serializer, direction, bypass_extensions)
                       ~~~~~~~~~~~~~~~~~~~~^^^^^^^^^^^^^^^^^^^^^^^^^^^^^^^^^^^^^^^^^^
  File "C:\Users\Administrator\AppData\Local\Packages\PythonSoftwareFoundation.Python.3.13_qbz5n2kfra8p0\LocalCache\local-packages\Python313\site-packages\drf_spectacular\openapi.py", line 949, in _map_serializer
    schema = self._map_basic_serializer(serializer, direction)
  File "C:\Users\Administrator\AppData\Local\Packages\PythonSoftwareFoundation.Python.3.13_qbz5n2kfra8p0\LocalCache\local-packages\Python313\site-packages\drf_spectacular\openapi.py", line 1042, in _map_basic_serializer
    for field in serializer.fields.values():
                 ^^^^^^^^^^^^^^^^^
  File "C:\Users\Administrator\AppData\Local\Packages\PythonSoftwareFoundation.Python.3.13_qbz5n2kfra8p0\LocalCache\local-packages\Python313\site-packages\django\utils\functional.py", line 47, in __get__
    res = instance.__dict__[self.name] = self.func(instance)
                                         ~~~~~~~~~^^^^^^^^^^
  File "C:\Users\Administrator\AppData\Local\Packages\PythonSoftwareFoundation.Python.3.13_qbz5n2kfra8p0\LocalCache\local-packages\Python313\site-packages\rest_framework\serializers.py", line 375, in fields
    fields[key] = value
    ~~~~~~^^^^^
  File "C:\Users\Administrator\AppData\Local\Packages\PythonSoftwareFoundation.Python.3.13_qbz5n2kfra8p0\LocalCache\local-packages\Python313\site-packages\rest_framework\utils\serializer_helpers.py", line 167, in __setitem__
    field.bind(field_name=key, parent=self.serializer)
    ~~~~~~~~~~^^^^^^^^^^^^^^^^^^^^^^^^^^^^^^^^^^^^^^^^
  File "C:\Users\Administrator\AppData\Local\Packages\PythonSoftwareFoundation.Python.3.13_qbz5n2kfra8p0\LocalCache\local-packages\Python313\site-packages\rest_framework\fields.py", line 358, in bind
    assert self.source != field_name, (
           ^^^^^^^^^^^^^^^^^^^^^^^^^
AssertionError: It is redundant to specify `source='display_name'` on field 'CharField' in serializer 'UserMinimalSerializer', because it is the same as the field name. Remove the `source` keyword argument.
ERROR 2025-04-21 23:44:05,676 basehttp "GET /api/v1/schema/ HTTP/1.1" 500 202876
INFO 2025-04-22 09:21:56,715 autoreload Watching for file changes with StatReloader
WARNING 2025-04-22 09:22:02,202 log Not Found: /
WARNING 2025-04-22 09:22:02,202 basehttp "GET / HTTP/1.1" 404 2644
WARNING 2025-04-22 09:22:02,415 log Not Found: /favicon.ico
WARNING 2025-04-22 09:22:02,415 basehttp "GET /favicon.ico HTTP/1.1" 404 2695
INFO 2025-04-22 09:22:07,596 basehttp "GET /admin HTTP/1.1" 301 0
INFO 2025-04-22 09:22:07,602 basehttp "GET /admin/ HTTP/1.1" 302 0
INFO 2025-04-22 09:22:07,616 basehttp "GET /admin/login/?next=/admin/ HTTP/1.1" 200 4198
INFO 2025-04-22 09:22:07,777 basehttp "GET /static/admin/css/dark_mode.css HTTP/1.1" 200 2808
INFO 2025-04-22 09:22:07,781 basehttp "GET /static/admin/js/theme.js HTTP/1.1" 200 1653
INFO 2025-04-22 09:22:07,782 basehttp "GET /static/admin/css/base.css HTTP/1.1" 200 22154
INFO 2025-04-22 09:22:07,838 basehttp "GET /static/admin/css/nav_sidebar.css HTTP/1.1" 200 2810
INFO 2025-04-22 09:22:07,838 basehttp "GET /static/admin/css/login.css HTTP/1.1" 200 951
INFO 2025-04-22 09:22:07,838 basehttp "GET /static/admin/css/responsive.css HTTP/1.1" 200 16632
INFO 2025-04-22 09:22:07,845 basehttp "GET /static/admin/js/nav_sidebar.js HTTP/1.1" 200 3063
INFO 2025-04-22 09:22:09,907 basehttp "POST /admin/login/?next=/admin/ HTTP/1.1" 200 4355
INFO 2025-04-22 09:22:12,479 basehttp "POST /admin/login/?next=/admin/ HTTP/1.1" 200 4355
INFO 2025-04-22 09:22:15,201 basehttp "POST /admin/login/?next=/admin/ HTTP/1.1" 302 0
INFO 2025-04-22 09:22:15,216 basehttp "GET /admin/ HTTP/1.1" 200 5515
INFO 2025-04-22 09:22:15,225 basehttp "GET /static/admin/css/dashboard.css HTTP/1.1" 200 441
INFO 2025-04-22 09:22:15,237 basehttp "GET /static/admin/img/icon-addlink.svg HTTP/1.1" 200 331
INFO 2025-04-22 09:22:15,237 basehttp "GET /static/admin/img/icon-changelink.svg HTTP/1.1" 200 380
INFO 2025-04-22 09:22:21,336 basehttp "GET /admin/auth/group/ HTTP/1.1" 200 7247
INFO 2025-04-22 09:22:21,347 basehttp "GET /static/admin/css/changelists.css HTTP/1.1" 200 6878
INFO 2025-04-22 09:22:21,348 basehttp "GET /static/admin/js/jquery.init.js HTTP/1.1" 200 347
INFO 2025-04-22 09:22:21,349 basehttp "GET /static/admin/js/core.js HTTP/1.1" 200 6208
INFO 2025-04-22 09:22:21,350 basehttp "GET /static/admin/js/admin/RelatedObjectLookups.js HTTP/1.1" 200 9777
INFO 2025-04-22 09:22:21,352 basehttp "GET /static/admin/js/actions.js HTTP/1.1" 200 8076
INFO 2025-04-22 09:22:21,353 basehttp "GET /static/admin/js/prepopulate.js HTTP/1.1" 200 1531
INFO 2025-04-22 09:22:21,353 basehttp "GET /admin/jsi18n/ HTTP/1.1" 200 9327
INFO 2025-04-22 09:22:21,353 basehttp "GET /static/admin/js/urlify.js HTTP/1.1" 200 7887
INFO 2025-04-22 09:22:21,354 basehttp "GET /static/admin/img/search.svg HTTP/1.1" 200 458
INFO 2025-04-22 09:22:21,355 basehttp "GET /static/admin/js/vendor/jquery/jquery.js HTTP/1.1" 200 285314
INFO 2025-04-22 09:22:21,356 basehttp "GET /static/admin/js/vendor/xregexp/xregexp.js HTTP/1.1" 200 325171
INFO 2025-04-22 09:22:21,358 basehttp "GET /static/admin/js/filters.js HTTP/1.1" 200 978
INFO 2025-04-22 09:22:21,369 basehttp "GET /static/admin/img/tooltag-add.svg HTTP/1.1" 200 331
INFO 2025-04-22 09:33:24,553 autoreload Watching for file changes with StatReloader
INFO 2025-04-22 09:33:33,770 basehttp "GET /admin/auth/group/ HTTP/1.1" 200 8038
INFO 2025-04-22 09:33:33,787 basehttp "GET /admin/jsi18n/ HTTP/1.1" 200 9327
INFO 2025-04-22 09:33:34,755 basehttp "GET /admin/auth/group/ HTTP/1.1" 200 8038
INFO 2025-04-22 09:33:34,768 basehttp "GET /admin/jsi18n/ HTTP/1.1" 200 9327
INFO 2025-04-22 09:33:35,497 basehttp "GET /admin/auth/group/ HTTP/1.1" 200 8038
INFO 2025-04-22 09:33:35,510 basehttp "GET /admin/jsi18n/ HTTP/1.1" 200 9327
INFO 2025-04-22 09:33:36,934 basehttp "GET /admin/common/apilog/ HTTP/1.1" 200 17344
INFO 2025-04-22 09:33:36,946 basehttp "GET /admin/jsi18n/ HTTP/1.1" 200 9327
INFO 2025-04-22 09:33:37,055 basehttp "GET /static/admin/img/sorting-icons.svg HTTP/1.1" 200 1097
INFO 2025-04-22 09:33:37,056 basehttp "GET /static/admin/img/icon-viewlink.svg HTTP/1.1" 200 581
INFO 2025-04-22 09:33:39,016 basehttp "GET /admin/auth/group/ HTTP/1.1" 200 8038
INFO 2025-04-22 09:33:39,029 basehttp "GET /admin/jsi18n/ HTTP/1.1" 200 9327
INFO 2025-04-22 09:33:39,890 basehttp "GET /admin/auth/group/ HTTP/1.1" 200 8038
INFO 2025-04-22 09:33:39,905 basehttp "GET /admin/jsi18n/ HTTP/1.1" 200 9327
INFO 2025-04-22 09:33:41,611 basehttp "GET /admin/ HTTP/1.1" 200 6475
INFO 2025-04-22 09:33:45,282 basehttp "GET /admin/ HTTP/1.1" 200 6475
INFO 2025-04-22 09:33:45,852 basehttp "GET /admin/ HTTP/1.1" 200 6475
INFO 2025-04-22 09:33:46,452 basehttp "GET /admin/ HTTP/1.1" 200 6475
INFO 2025-04-22 09:33:46,653 basehttp "GET /admin/ HTTP/1.1" 200 6475
INFO 2025-04-22 09:33:46,839 basehttp "GET /admin/ HTTP/1.1" 200 6475
INFO 2025-04-22 09:33:47,035 basehttp "GET /admin/ HTTP/1.1" 200 6475
INFO 2025-04-22 09:33:48,979 basehttp "GET /admin/common/apilog/ HTTP/1.1" 200 17344
INFO 2025-04-22 09:33:48,991 basehttp "GET /admin/jsi18n/ HTTP/1.1" 200 9327
INFO 2025-04-22 09:34:04,524 basehttp "GET /admin/auth/group/ HTTP/1.1" 200 8038
INFO 2025-04-22 09:34:04,539 basehttp "GET /admin/jsi18n/ HTTP/1.1" 200 9327
INFO 2025-04-22 09:34:05,826 basehttp "GET /admin/common/apilog/ HTTP/1.1" 200 17344
INFO 2025-04-22 09:34:05,839 basehttp "GET /admin/jsi18n/ HTTP/1.1" 200 9327
INFO 2025-04-22 09:34:10,378 basehttp "GET /admin/common/ HTTP/1.1" 200 5376
INFO 2025-04-22 09:34:11,211 basehttp "GET /admin/ HTTP/1.1" 200 6475
